try{
    console.log('We are inside try block')
    functionharry(ee) 
}catch(e){
    console.log('Are you okay?')
    console.log('error name',e.name)
    console.log('error message',e.message)
}finally{
    console.log('Finally we will run these')
}

 